Workbook

Sheet Detalles movimientos
C2: VENTAS GRANEL ECOGAS SPA
C4: Fecha | D4: Nombre Cliente | E4: Camión | F4: Vende | G4: Dirección | H4: Precio | I4: Litros Vendidos | K4: Cuenta litros | L4: Extraccion | M4: Total Recaudado | N4: Medio de pago | O4: Comisiones | P4: Observación | Q4: COMPRA ENAP | R4: Litros Comprados | T4: _Idx_CJ | U4: _Idx_Ignacio | V4: _Idx_Tripulacion | W4: _Idx_ENAP carga
C5: 46226 | D5: ENAP carga | E5: VJYL61 | F5: ENAP carga | N5: ENAP carga | O5: =IF(F5="CJ", I5*200, "") | P5: Guía N° xxxxx | Q5: 3836889 | R5: 11481 | T5: =IF(F5="CJ", COUNTIF(F$5:F5, "CJ"), "") | U5: =IF(F5="Ignacio", COUNTIF(F$5:F5, "Ignacio"), "") | V5: =IF(F5="Tripulacion", COUNTIF(F$5:F5, "Tripulacion"), "") | W5: =IF(F5="ENAP carga", COUNTIF(F$5:F5, "ENAP carga"), "")
C6: 46230 | D6: Ignacio Guerrero | E6: VJYL61 | F6: Ignacio | L6: 1403 | N6: Extraccion | O6: =IF(F6="CJ", I6*200, "") | P6: Extraccion | T6: =IF(F6="CJ", COUNTIF(F$5:F6, "CJ"), "") | U6: =IF(F6="Ignacio", COUNTIF(F$5:F6, "Ignacio"), "") | V6: =IF(F6="Tripulacion", COUNTIF(F$5:F6, "Tripulacion"), "") | W6: =IF(F6="ENAP carga", COUNTIF(F$5:F6, "ENAP carga"), "")
C7: 46230 | D7: Ricardo Brisas del Raco | E7: VJYL61 | F7: CJ | G7: Brisas del Raco | H7: 1000 | I7: 179.2 | M7: =H7*I7 | N7: Tarjeta | O7: =I7*200 | P7: Comision Pagada | T7: =IF(F7="CJ", COUNTIF(F$5:F7, "CJ"), "") | U7: =IF(F7="Ignacio", COUNTIF(F$5:F7, "Ignacio"), "") | V7: =IF(F7="Tripulacion", COUNTIF(F$5:F7, "Tripulacion"), "") | W7: =IF(F7="ENAP carga", COUNTIF(F$5:F7, "ENAP carga"), "")
C8: 46230 | D8: Ale Turko | E8: VJYL61 | F8: CJ | H8: 1000 | I8: 518.1 | M8: =H8*I8 | N8: Pendiente de pago | O8: =I8*200 | P8: Comision Pagada | T8: =IF(F8="CJ", COUNTIF(F$5:F8, "CJ"), "") | U8: =IF(F8="Ignacio", COUNTIF(F$5:F8, "Ignacio"), "") | V8: =IF(F8="Tripulacion", COUNTIF(F$5:F8, "Tripulacion"), "") | W8: =IF(F8="ENAP carga", COUNTIF(F$5:F8, "ENAP carga"), "")
C9: 46230 | D9: Tirua | E9: VJYL61 | F9: CJ | H9: 1000 | I9: 488.2 | M9: =H9*I9 | N9: Pagado | O9: =I9*200 | P9: Comision Pagada | T9: =IF(F9="CJ", COUNTIF(F$5:F9, "CJ"), "") | U9: =IF(F9="Ignacio", COUNTIF(F$5:F9, "Ignacio"), "") | V9: =IF(F9="Tripulacion", COUNTIF(F$5:F9, "Tripulacion"), "") | W9: =IF(F9="ENAP carga", COUNTIF(F$5:F9, "ENAP carga"), "")
C10: 46230 | D10: Ciao Italia | E10: VJYL61 | F10: CJ | H10: 1000 | I10: 500.3 | M10: =H10*I10 | N10: Pagado | O10: =I10*200 | P10: Comision Pagada | T10: =IF(F10="CJ", COUNTIF(F$5:F10, "CJ"), "") | U10: =IF(F10="Ignacio", COUNTIF(F$5:F10, "Ignacio"), "") | V10: =IF(F10="Tripulacion", COUNTIF(F$5:F10, "Tripulacion"), "") | W10: =IF(F10="ENAP carga", COUNTIF(F$5:F10, "ENAP carga"), "")
C11: 46230 | D11: Claudio Ulloa | E11: VJYL61 | F11: CJ | H11: 1000 | I11: 237.9 | M11: =H11*I11 | N11: Pagado | O11: =I11*200 | P11: Comision Pagada | T11: =IF(F11="CJ", COUNTIF(F$5:F11, "CJ"), "") | U11: =IF(F11="Ignacio", COUNTIF(F$5:F11, "Ignacio"), "") | V11: =IF(F11="Tripulacion", COUNTIF(F$5:F11, "Tripulacion"), "") | W11: =IF(F11="ENAP carga", COUNTIF(F$5:F11, "ENAP carga"), "")
C12: 46230 | D12: Francisco Ulloa | E12: VJYL61 | F12: CJ | H12: 1000 | I12: 205.1 | M12: =H12*I12 | N12: Pagado | O12: =I12*200 | P12: Comision Pagada | T12: =IF(F12="CJ", COUNTIF(F$5:F12, "CJ"), "") | U12: =IF(F12="Ignacio", COUNTIF(F$5:F12, "Ignacio"), "") | V12: =IF(F12="Tripulacion", COUNTIF(F$5:F12, "Tripulacion"), "") | W12: =IF(F12="ENAP carga", COUNTIF(F$5:F12, "ENAP carga"), "")
C13: 46230 | D13: Alicia Pavez | E13: VJYL61 | F13: CJ | H13: 1000 | I13: 300 | M13: =H13*I13 | N13: Pendiente de pago | O13: =I13*200 | P13: Comision Pagada | S13: =SUM(I7:I13) | T13: =IF(F13="CJ", COUNTIF(F$5:F13, "CJ"), "") | U13: =IF(F13="Ignacio", COUNTIF(F$5:F13, "Ignacio"), "") | V13: =IF(F13="Tripulacion", COUNTIF(F$5:F13, "Tripulacion"), "") | W13: =IF(F13="ENAP carga", COUNTIF(F$5:F13, "ENAP carga"), "")
C14: 46231 | D14: Vanessa | E14: VJYL61 | F14: CJ | H14: 1000 | I14: 200 | M14: =H14*I14 | N14: Transferencia | O14: =IF(F14="CJ", I14*200, "") | T14: =IF(F14="CJ", COUNTIF(F$5:F14, "CJ"), "") | U14: =IF(F14="Ignacio", COUNTIF(F$5:F14, "Ignacio"), "") | V14: =IF(F14="Tripulacion", COUNTIF(F$5:F14, "Tripulacion"), "") | W14: =IF(F14="ENAP carga", COUNTIF(F$5:F14, "ENAP carga"), "")
C15: 46231 | D15: Franco Garcia | E15: VJYL61 | F15: Tripulacion | G15: Santa Rita 1177 parcela 14 Pirque | H15: 0 | I15: 912 | K15: 13789 | M15: =H15*I15 | O15: =IF(F15="CJ", I15*200, "") | T15: =IF(F15="CJ", COUNTIF(F$5:F15, "CJ"), "") | U15: =IF(F15="Ignacio", COUNTIF(F$5:F15, "Ignacio"), "") | V15: =IF(F15="Tripulacion", COUNTIF(F$5:F15, "Tripulacion"), "") | W15: =IF(F15="ENAP carga", COUNTIF(F$5:F15, "ENAP carga"), "")
C16: 46233 | D16: Simon | E16: VJYL61 | F16: CJ | G16: Camino el Chalaco 66B | H16: 1000 | I16: 747 | J16: =K16-K15 | K16: 14535 | M16: =H16*I16 | N16: Transferencia | O16: =IF(F16="CJ", I16*200, "") | P16: Factura | S16: Ebal spa - RUT: 77.625.623-4 - Av Gabriela 3264 La Pintana - Giro Construccion | T16: =IF(F16="CJ", COUNTIF(F$5:F16, "CJ"), "") | U16: =IF(F16="Ignacio", COUNTIF(F$5:F16, "Ignacio"), "") | V16: =IF(F16="Tripulacion", COUNTIF(F$5:F16, "Tripulacion"), "") | W16: =IF(F16="ENAP carga", COUNTIF(F$5:F16, "ENAP carga"), "")
C17: 46237 | D17: Manuel Vergara Ricci | E17: VJYL61 | F17: CJ | G17: Avenida Virginia subercaseaux 4175 (parcela 15) | H17: 1100 | I17: 200 | J17: =K17-K16 | K17: 14735 | M17: =H17*I17 | N17: Transferencia | O17: =IF(F17="CJ", I17*200, "") | T17: =IF(F17="CJ", COUNTIF(F$5:F17, "CJ"), "") | U17: =IF(F17="Ignacio", COUNTIF(F$5:F17, "Ignacio"), "") | V17: =IF(F17="Tripulacion", COUNTIF(F$5:F17, "Tripulacion"), "") | W17: =IF(F17="ENAP carga", COUNTIF(F$5:F17, "ENAP carga"), "")
C18: 46237 | D18: Gabriela Rojas | E18: VJYL61 | F18: CJ | G18: Camino de las flores 1262 Pirque | H18: 1100 | I18: 350 | J18: =K18-K17 | K18: 16490 | M18: =H18*I18 | N18: Transferencia en dos | O18: =IF(F18="CJ", I18*200, "") | P18: Quedó saldo de $35 mil para mañana | T18: =IF(F18="CJ", COUNTIF(F$5:F18, "CJ"), "") | U18: =IF(F18="Ignacio", COUNTIF(F$5:F18, "Ignacio"), "") | V18: =IF(F18="Tripulacion", COUNTIF(F$5:F18, "Tripulacion"), "") | W18: =IF(F18="ENAP carga", COUNTIF(F$5:F18, "ENAP carga"), "")
C19: 46238 | D19: Ignacio Guerrero | E19: VJYL61 | F19: Ignacio | L19: 1403 | N19: Extraccion | O19: =IF(F19="CJ", L19*200, "") | P19: Extraccion | T19: =IF(F19="CJ", COUNTIF(F$5:F19, "CJ"), "") | U19: =IF(F19="Ignacio", COUNTIF(F$5:F19, "Ignacio"), "") | V19: =IF(F19="Tripulacion", COUNTIF(F$5:F19, "Tripulacion"), "") | W19: =IF(F19="ENAP carga", COUNTIF(F$5:F19, "ENAP carga"), "")
C20: 46239 | D20: Casa de Reposo Brisas | E20: VJYL61 | F20: CJ | G20: Brisas del raco parcela 36 Pirque | H20: 1100 | I20: 270 | J20: =K20-K18 | K20: 16760 | M20: =H20*I20 | N20: Transferencia | O20: =IF(F20="CJ", I20*200, "") | P20: Factura | S20: Residencia Adulto Mayor Amor Eterno SpA - Rut 76.699.397-4 - Los Almendros Parcela2B Pirque | T20: =IF(F20="CJ", COUNTIF(F$5:F20, "CJ"), "") | U20: =IF(F20="Ignacio", COUNTIF(F$5:F20, "Ignacio"), "") | V20: =IF(F20="Tripulacion", COUNTIF(F$5:F20, "Tripulacion"), "") | W20: =IF(F20="ENAP carga", COUNTIF(F$5:F20, "ENAP carga"), "")
C21: 46241 | D21: Gastronomca Exquisite | E21: VJYL61 | F21: Tripulacion | G21: JP Alesaandri 114 Nuñoa | H21: 1000 | I21: 350 | J21: =K21-K20 | K21: 17110 | M21: =H21*I21 | N21: Transferencia | O21: =IF(F21="CJ", I21*200, "") | P21: Factura | S21: Gastronomica Exquisite SpA - Rut: 77.714.318-2 - JP alessandri 114 Nuñoa | T21: =IF(F21="CJ", COUNTIF(F$5:F21, "CJ"), "") | U21: =IF(F21="Ignacio", COUNTIF(F$5:F21, "Ignacio"), "") | V21: =IF(F21="Tripulacion", COUNTIF(F$5:F21, "Tripulacion"), "") | W21: =IF(F21="ENAP carga", COUNTIF(F$5:F21, "ENAP carga"), "")
C22: 46241 | D22: Panaderia Maipu | E22: VJYL61 | F22: Tripulacion | G22: Av los carreras 706B, plaza de los porotos | H22: 1000 | I22: 109 | J22: =K22-K21 | K22: 17219 | M22: =H22*I22 | N22: Transferencia | O22: =IF(F22="CJ", I22*200, "") | T22: =IF(F22="CJ", COUNTIF(F$5:F22, "CJ"), "") | U22: =IF(F22="Ignacio", COUNTIF(F$5:F22, "Ignacio"), "") | V22: =IF(F22="Tripulacion", COUNTIF(F$5:F22, "Tripulacion"), "") | W22: =IF(F22="ENAP carga", COUNTIF(F$5:F22, "ENAP carga"), "")
C23: 46242 | D23: Ignacio Guerrero | E23: VJYL61 | F23: Ignacio | L23: 2219 | N23: Extraccion | O23: =IF(F23="CJ", L23*200, "") | P23: Extraccion | T23: =IF(F23="CJ", COUNTIF(F$5:F23, "CJ"), "") | U23: =IF(F23="Ignacio", COUNTIF(F$5:F23, "Ignacio"), "") | V23: =IF(F23="Tripulacion", COUNTIF(F$5:F23, "Tripulacion"), "") | W23: =IF(F23="ENAP carga", COUNTIF(F$5:F23, "ENAP carga"), "")
C24: 46245 | D24: Eli Ciao Italia | E24: VJYL61 | F24: CJ | G24: Camino rinconada san Vicente parcela 38 | H24: 1100 | I24: 404 | J24: =K24-K22 | K24: 19834 | M24: =H24*I24 | N24: Transferencia | O24: =IF(F24="CJ", I24*200, "") | T24: =IF(F24="CJ", COUNTIF(F$5:F24, "CJ"), "") | U24: =IF(F24="Ignacio", COUNTIF(F$5:F24, "Ignacio"), "") | V24: =IF(F24="Tripulacion", COUNTIF(F$5:F24, "Tripulacion"), "") | W24: =IF(F24="ENAP carga", COUNTIF(F$5:F24, "ENAP carga"), "")
C25: 46245 | D25: Javier Quiroz | E25: VJYL61 | F25: CJ | G25: Condominio majadas C parcela 5 | H25: 1100 | I25: 509 | J25: =K25-K24 | K25: 20343 | M25: =H25*I25 | N25: Transferencia | O25: =IF(F25="CJ", I25*200, "") | T25: =IF(F25="CJ", COUNTIF(F$5:F25, "CJ"), "") | U25: =IF(F25="Ignacio", COUNTIF(F$5:F25, "Ignacio"), "") | V25: =IF(F25="Tripulacion", COUNTIF(F$5:F25, "Tripulacion"), "") | W25: =IF(F25="ENAP carga", COUNTIF(F$5:F25, "ENAP carga"), "")
C26: 46246 | D26: ENAP carga | E26: VJYL42 | F26: ENAP carga | M26: =H26*I26 | N26: ENAP carga | O26: =IF(F26="CJ", I26*200, "") | P26: Guía N° 2356186 | Q26: 3882182 | R26: 11617 | T26: =IF(F26="CJ", COUNTIF(F$5:F26, "CJ"), "") | U26: =IF(F26="Ignacio", COUNTIF(F$5:F26, "Ignacio"), "") | V26: =IF(F26="Tripulacion", COUNTIF(F$5:F26, "Tripulacion"), "") | W26: =IF(F26="ENAP carga", COUNTIF(F$5:F26, "ENAP carga"), "")
C27: 46247 | D27: Ignacio Guerrero | E27: VJYL42 | F27: Ignacio | L27: 11539 | M27: =H27*I27 | N27: Extraccion | O27: =IF(F27="CJ", I27*200, "") | P27: Extraccion | T27: =IF(F27="CJ", COUNTIF(F$5:F27, "CJ"), "") | U27: =IF(F27="Ignacio", COUNTIF(F$5:F27, "Ignacio"), "") | V27: =IF(F27="Tripulacion", COUNTIF(F$5:F27, "Tripulacion"), "") | W27: =IF(F27="ENAP carga", COUNTIF(F$5:F27, "ENAP carga"), "")
C28: 46247 | D28: ENAP carga | E28: VJYL61 | F28: ENAP carga | M28: =H28*I28 | N28: ENAP carga | O28: =IF(F28="CJ", I28*200, "") | P28: Guía N° 2356453 | Q28: 3836889 | R28: 11481 | T28: =IF(F28="CJ", COUNTIF(F$5:F28, "CJ"), "") | U28: =IF(F28="Ignacio", COUNTIF(F$5:F28, "Ignacio"), "") | V28: =IF(F28="Tripulacion", COUNTIF(F$5:F28, "Tripulacion"), "") | W28: =IF(F28="ENAP carga", COUNTIF(F$5:F28, "ENAP carga"), "")
C29: 46247 | D29: Mister Guss SpA | E29: VJYL61 | F29: Tripulacion | G29: PRIMERA TRANSVERSAL 828 PADRE HURTADO | H29: 1000 | I29: 256 | K29: 22615 | M29: =H29*I29 | N29: Transferencia | O29: =IF(F29="CJ", I29*200, "") | P29: Factura | S29: MISTER GUSS SPA - RUT 78.060.801-3 - PRIMERA TRANSVERSAL 828 PADRE HURTADO - RESTOBAR | T29: =IF(F29="CJ", COUNTIF(F$5:F29, "CJ"), "") | U29: =IF(F29="Ignacio", COUNTIF(F$5:F29, "Ignacio"), "") | V29: =IF(F29="Tripulacion", COUNTIF(F$5:F29, "Tripulacion"), "") | W29: =IF(F29="ENAP carga", COUNTIF(F$5:F29, "ENAP carga"), "")
C30: 46248 | D30: ENAP carga | E30: VJYL42 | F30: ENAP carga | N30: ENAP carga | O30: =IF(F30="CJ", I30*200, "") | P30: Guía N° 2356889 | Q30: 3955528 | R30: 11656 | T30: =IF(F30="CJ", COUNTIF(F$5:F30, "CJ"), "") | U30: =IF(F30="Ignacio", COUNTIF(F$5:F30, "Ignacio"), "") | V30: =IF(F30="Tripulacion", COUNTIF(F$5:F30, "Tripulacion"), "") | W30: =IF(F30="ENAP carga", COUNTIF(F$5:F30, "ENAP carga"), "")
C31: 46251 | D31: Ignacio Guerrero | E31: VJYL42 | F31: Ignacio | L31: 11344 | N31: Extraccion | P31: Extraccion
C32: 46252 | D32: ENAP carga | E32: VJYL42 | F32: ENAP carga | N32: ENAP carga | O32: =IF(F32="CJ", I32*200, "") | P32: Guía N° 2358078 | Q32: 3889821 | R32: 11462 | T32: =IF(F32="CJ", COUNTIF(F$5:F32, "CJ"), "") | U32: =IF(F32="Ignacio", COUNTIF(F$5:F32, "Ignacio"), "") | V32: =IF(F32="Tripulacion", COUNTIF(F$5:F32, "Tripulacion"), "") | W32: =IF(F32="ENAP carga", COUNTIF(F$5:F32, "ENAP carga"), "")
C33: 46253 | D33: ENAP carga | E33: VJYL42 | F33: ENAP carga | N33: ENAP carga | O33: =IF(F33="CJ", I33*200, "") | P33: Guía N° 2358522 | Q33: 3830686 | R33: 11288 | T33: =IF(F33="CJ", COUNTIF(F$5:F33, "CJ"), "") | U33: =IF(F33="Ignacio", COUNTIF(F$5:F33, "Ignacio"), "") | V33: =IF(F33="Tripulacion", COUNTIF(F$5:F33, "Tripulacion"), "") | W33: =IF(F33="ENAP carga", COUNTIF(F$5:F33, "ENAP carga"), "")
C34: 46253 | D34: Ignacio Guerrero | E34: VJYL42 | F34: Ignacio | L34: 11225 | N34: Extraccion | P34: Extraccion
C35: 46254 | D35: Ignacio Guerrero | E35: VJYL42 | F35: Ignacio | L35: 11088 | N35: Extraccion | P35: Extraccion
C36: 46254 | D36: Bar Barrio Alto | E36: VJYL61 | F36: CJ | G36: El Peñón 335 Puente Alto | H36: 1000 | I36: 294 | J36: =K36-K29 | K36: 22909 | M36: =H36*I36 | N36: Transferencia dos | O36: =IF(F36="CJ", I36*200, "") | P36: Factura | S36: Centro de eventos Barrio Alto SpA - RUT 78.467.844-K - EL PENON CHICO 0335 PUENTE ALTO | T36: =IF(F36="CJ", COUNTIF(F$5:F36, "CJ"), "") | U36: =IF(F36="Ignacio", COUNTIF(F$5:F36, "Ignacio"), "") | V36: =IF(F36="Tripulacion", COUNTIF(F$5:F36, "Tripulacion"), "") | W36: =IF(F36="ENAP carga", COUNTIF(F$5:F36, "ENAP carga"), "")
C37: 46254 | D37: BAR Tirua | E37: VJYL61 | F37: CJ | G37: Pirque | H37: 1100 | I37: 500 | J37: =K37-K36 | K37: 23409 | M37: =H37*I37 | N37: Pendiente de pago | O37: =IF(F37="CJ", I37*200, "") | T37: =IF(F37="CJ", COUNTIF(F$5:F37, "CJ"), "") | U37: =IF(F37="Ignacio", COUNTIF(F$5:F37, "Ignacio"), "") | V37: =IF(F37="Tripulacion", COUNTIF(F$5:F37, "Tripulacion"), "") | W37: =IF(F37="ENAP carga", COUNTIF(F$5:F37, "ENAP carga"), "")
C38: 46254 | D38: Brasas y Sabor SpA | E38: VJYL61 | F38: Tripulacion | G38: Puente Alto | H38: 1100 | I38: 100 | J38: =K38-K37 | K38: 23509 | M38: =H38*I38 | N38: Transferencia | O38: =IF(F38="CJ", I38*200, "") | P38: Factura | S38: Brasas y Sabor SpA - RUT 76.378-704-4 - Av Concha y Toro #11 Puente Alto | T38: =IF(F38="CJ", COUNTIF(F$5:F38, "CJ"), "") | U38: =IF(F38="Ignacio", COUNTIF(F$5:F38, "Ignacio"), "") | V38: =IF(F38="Tripulacion", COUNTIF(F$5:F38, "Tripulacion"), "") | W38: =IF(F38="ENAP carga", COUNTIF(F$5:F38, "ENAP carga"), "")
C39: 46258 | D39: Franco Garcia | E39: VJYL61 | F39: Tripulacion | G39: Santa Rita 1177 parcela 14 Pirque | H39: 0 | I39: 1120 | J39: =K39-K38 | K39: 24630 | M39: =H39*I39 | O39: =IF(F39="CJ", I39*200, "") | T39: =IF(F39="CJ", COUNTIF(F$5:F39, "CJ"), "") | U39: =IF(F39="Ignacio", COUNTIF(F$5:F39, "Ignacio"), "") | V39: =IF(F39="Tripulacion", COUNTIF(F$5:F39, "Tripulacion"), "") | W39: =IF(F39="ENAP carga", COUNTIF(F$5:F39, "ENAP carga"), "")
C40: 46258 | D40: Centro de Eventos Barrio Alto SpA | E40: VJYL61 | F40: Tripulacion | G40: El Peñón 335 Puente Alto | H40: 1000 | I40: 449 | J40: =K40-K39 | K40: 25078 | M40: =H40*I40 | N40: Transferencia | O40: =IF(F40="CJ", I40*200, "") | P40: Factura | S40: Centro de eventos Barrio Alto SpA - RUT 78.467.844-K - EL PENON CHICO 0335 PUENTE ALTO | T40: =IF(F40="CJ", COUNTIF(F$5:F40, "CJ"), "") | U40: =IF(F40="Ignacio", COUNTIF(F$5:F40, "Ignacio"), "") | V40: =IF(F40="Tripulacion", COUNTIF(F$5:F40, "Tripulacion"), "") | W40: =IF(F40="ENAP carga", COUNTIF(F$5:F40, "ENAP carga"), "")
C41: 46259 | D41: ENAP carga | E41: VJYL42 | F41: ENAP carga | N41: ENAP carga | O41: =IF(F41="CJ", I41*200, "") | P41: Guía N° 2360214 | Q41: 3772187 | R41: 11288 | T41: =IF(F41="CJ", COUNTIF(F$5:F41, "CJ"), "") | U41: =IF(F41="Ignacio", COUNTIF(F$5:F41, "Ignacio"), "") | V41: =IF(F41="Tripulacion", COUNTIF(F$5:F41, "Tripulacion"), "") | W41: =IF(F41="ENAP carga", COUNTIF(F$5:F41, "ENAP carga"), "")
C42: 46260 | D42: ENAP carga | E42: VJYL42 | F42: ENAP carga | N42: ENAP carga | O42: =IF(F42="CJ", I42*200, "") | P42: Guía N° 2360596 | Q42: 3571608 | R42: 10688 | T42: =IF(F42="CJ", COUNTIF(F$5:F42, "CJ"), "") | U42: =IF(F42="Ignacio", COUNTIF(F$5:F42, "Ignacio"), "") | V42: =IF(F42="Tripulacion", COUNTIF(F$5:F42, "Tripulacion"), "") | W42: =IF(F42="ENAP carga", COUNTIF(F$5:F42, "ENAP carga"), "")
...

Sheet ENAP
B2: RESUMEN Y MOVIMIENTOS INDIVIDUALES: ENAP CARGA
B3: Sincronización en tiempo real con la pestaña 'Detalles movimientos'
B5: LITROS VENDIDOS | C5: LITROS COMPRADOS | D5: STOCK ACTUAL | E5: TOTAL VENTAS ($) | F5: N° OPERACIONES
B6: =SUMIFS('Detalles movimientos'!I$5:I$1021, 'Detalles movimientos'!F$5:F$1021, "ENAP carga") | C6: =SUMIFS('Detalles movimientos'!R$5:R$1021, 'Detalles movimientos'!F$5:F$1021, "ENAP carga") | D6: =C6-B6 | E6: =SUMIFS('Detalles movimientos'!M$5:M$1021, 'Detalles movimientos'!F$5:F$1021, "ENAP carga") | F6: =COUNTIFS('Detalles movimientos'!F$5:F$1021, "ENAP carga")
B9: Fecha | C9: Nombre Cliente | D9: Camión | E9: Vende | F9: Dirección | G9: Precio | H9: Litros | I9: Total | J9: Medio de pago | K9: Comisiones | L9: Observación | M9: Facturación / Detalles
B10: =IFERROR(INDEX('Detalles movimientos'!C$5:C$1021, MATCH(1, 'Detalles movimientos'!$W$5:$W$1021, 0)), "") | C10: =IFERROR(INDEX('Detalles movimientos'!D$5:D$1021, MATCH(1, 'Detalles movimientos'!$W$5:$W$1021, 0)), "") | D10: =IFERROR(INDEX('Detalles movimientos'!E$5:E$1021, MATCH(1, 'Detalles movimientos'!$W$5:$W$1021, 0)), "") | E10: =IFERROR(INDEX('Detalles movimientos'!F$5:F$1021, MATCH(1, 'Detalles movimientos'!$W$5:$W$1021, 0)), "") | F10: =IFERROR(INDEX('Detalles movimientos'!G$5:G$1021, MATCH(1, 'Detalles movimientos'!$W$5:$W$1021, 0)), "") | G10: =IFERROR(INDEX('Detalles movimientos'!H$5:H$1021, MATCH(1, 'Detalles movimientos'!$W$5:$W$1021, 0)), "") | H10: =IFERROR(INDEX('Detalles movimientos'!I$5:I$1021, MATCH(1, 'Detalles movimientos'!$W$5:$W$1021, 0)), "") | I10: =IFERROR(INDEX('Detalles movimientos'!M$5:M$1021, MATCH(1, 'Detalles movimientos'!$W$5:$W$1021, 0)), "") | J10: =IFERROR(INDEX('Detalles movimientos'!N$5:N$1021, MATCH(1, 'Detalles movimientos'!$W$5:$W$1021, 0)), "") | K10: =IFERROR(INDEX('Detalles movimientos'!O$5:O$1021, MATCH(1, 'Detalles movimientos'!$W$5:$W$1021, 0)), "") | L10: =IFERROR(INDEX('Detalles movimientos'!P$5:P$1021, MATCH(1, 'Detalles movimientos'!$W$5:$W$1021, 0)), "") | M10: =IFERROR(INDEX('Detalles movimientos'!S$5:S$1021, MATCH(1, 'Detalles movimientos'!$W$5:$W$1021, 0)), "")
B11: =IFERROR(INDEX('Detalles movimientos'!C$5:C$1021, MATCH(2, 'Detalles movimientos'!$W$5:$W$1021, 0)), "") | C11: =IFERROR(INDEX('Detalles movimientos'!D$5:D$1021, MATCH(2, 'Detalles movimientos'!$W$5:$W$1021, 0)), "") | D11: =IFERROR(INDEX('Detalles movimientos'!E$5:E$1021, MATCH(2, 'Detalles movimientos'!$W$5:$W$1021, 0)), "") | E11: =IFERROR(INDEX('Detalles movimientos'!F$5:F$1021, MATCH(2, 'Detalles movimientos'!$W$5:$W$1021, 0)), "") | F11: =IFERROR(INDEX('Detalles movimientos'!G$5:G$1021, MATCH(2, 'Detalles movimientos'!$W$5:$W$1021, 0)), "") | G11: =IFERROR(INDEX('Detalles movimientos'!H$5:H$1021, MATCH(2, 'Detalles movimientos'!$W$5:$W$1021, 0)), "") | H11: =IFERROR(INDEX('Detalles movimientos'!I$5:I$1021, MATCH(2, 'Detalles movimientos'!$W$5:$W$1021, 0)), "") | I11: =IFERROR(INDEX('Detalles movimientos'!M$5:M$1021, MATCH(2, 'Detalles movimientos'!$W$5:$W$1021, 0)), "") | J11: =IFERROR(INDEX('Detalles movimientos'!N$5:N$1021, MATCH(2, 'Detalles movimientos'!$W$5:$W$1021, 0)), "") | K11: =IFERROR(INDEX('Detalles movimientos'!O$5:O$1021, MATCH(2, 'Detalles movimientos'!$W$5:$W$1021, 0)), "") | L11: =IFERROR(INDEX('Detalles movimientos'!P$5:P$1021, MATCH(2, 'Detalles movimientos'!$W$5:$W$1021, 0)), "") | M11: =IFERROR(INDEX('Detalles movimientos'!S$5:S$1021, MATCH(2, 'Detalles movimientos'!$W$5:$W$1021, 0)), "")
B12: =IFERROR(INDEX('Detalles movimientos'!C$5:C$1021, MATCH(3, 'Detalles movimientos'!$W$5:$W$1021, 0)), "") | C12: =IFERROR(INDEX('Detalles movimientos'!D$5:D$1021, MATCH(3, 'Detalles movimientos'!$W$5:$W$1021, 0)), "") | D12: =IFERROR(INDEX('Detalles movimientos'!E$5:E$1021, MATCH(3, 'Detalles movimientos'!$W$5:$W$1021, 0)), "") | E12: =IFERROR(INDEX('Detalles movimientos'!F$5:F$1021, MATCH(3, 'Detalles movimientos'!$W$5:$W$1021, 0)), "") | F12: =IFERROR(INDEX('Detalles movimientos'!G$5:G$1021, MATCH(3, 'Detalles movimientos'!$W$5:$W$1021, 0)), "") | G12: =IFERROR(INDEX('Detalles movimientos'!H$5:H$1021, MATCH(3, 'Detalles movimientos'!$W$5:$W$1021, 0)), "") | H12: =IFERROR(INDEX('Detalles movimientos'!I$5:I$1021, MATCH(3, 'Detalles movimientos'!$W$5:$W$1021, 0)), "") | I12: =IFERROR(INDEX('Detalles movimientos'!M$5:M$1021, MATCH(3, 'Detalles movimientos'!$W$5:$W$1021, 0)), "") | J12: =IFERROR(INDEX('Detalles movimientos'!N$5:N$1021, MATCH(3, 'Detalles movimientos'!$W$5:$W$1021, 0)), "") | K12: =IFERROR(INDEX('Detalles movimientos'!O$5:O$1021, MATCH(3, 'Detalles movimientos'!$W$5:$W$1021, 0)), "") | L12: =IFERROR(INDEX('Detalles movimientos'!P$5:P$1021, MATCH(3, 'Detalles movimientos'!$W$5:$W$1021, 0)), "") | M12: =IFERROR(INDEX('Detalles movimientos'!S$5:S$1021, MATCH(3, 'Detalles movimientos'!$W$5:$W$1021, 0)), "")
B13: =IFERROR(INDEX('Detalles movimientos'!C$5:C$1021, MATCH(4, 'Detalles movimientos'!$W$5:$W$1021, 0)), "") | C13: =IFERROR(INDEX('Detalles movimientos'!D$5:D$1021, MATCH(4, 'Detalles movimientos'!$W$5:$W$1021, 0)), "") | D13: =IFERROR(INDEX('Detalles movimientos'!E$5:E$1021, MATCH(4, 'Detalles movimientos'!$W$5:$W$1021, 0)), "") | E13: =IFERROR(INDEX('Detalles movimientos'!F$5:F$1021, MATCH(4, 'Detalles movimientos'!$W$5:$W$1021, 0)), "") | F13: =IFERROR(INDEX('Detalles movimientos'!G$5:G$1021, MATCH(4, 'Detalles movimientos'!$W$5:$W$1021, 0)), "") | G13: =IFERROR(INDEX('Detalles movimientos'!H$5:H$1021, MATCH(4, 'Detalles movimientos'!$W$5:$W$1021, 0)), "") | H13: =IFERROR(INDEX('Detalles movimientos'!I$5:I$1021, MATCH(4, 'Detalles movimientos'!$W$5:$W$1021, 0)), "") | I13: =IFERROR(INDEX('Detalles movimientos'!M$5:M$1021, MATCH(4, 'Detalles movimientos'!$W$5:$W$1021, 0)), "") | J13: =IFERROR(INDEX('Detalles movimientos'!N$5:N$1021, MATCH(4, 'Detalles movimientos'!$W$5:$W$1021, 0)), "") | K13: =IFERROR(INDEX('Detalles movimientos'!O$5:O$1021, MATCH(4, 'Detalles movimientos'!$W$5:$W$1021, 0)), "") | L13: =IFERROR(INDEX('Detalles movimientos'!P$5:P$1021, MATCH(4, 'Detalles movimientos'!$W$5:$W$1021, 0)), "") | M13: =IFERROR(INDEX('Detalles movimientos'!S$5:S$1021, MATCH(4, 'Detalles movimientos'!$W$5:$W$1021, 0)), "")
B14: =IFERROR(INDEX('Detalles movimientos'!C$5:C$1021, MATCH(5, 'Detalles movimientos'!$W$5:$W$1021, 0)), "") | C14: =IFERROR(INDEX('Detalles movimientos'!D$5:D$1021, MATCH(5, 'Detalles movimientos'!$W$5:$W$1021, 0)), "") | D14: =IFERROR(INDEX('Detalles movimientos'!E$5:E$1021, MATCH(5, 'Detalles movimientos'!$W$5:$W$1021, 0)), "") | E14: =IFERROR(INDEX('Detalles movimientos'!F$5:F$1021, MATCH(5, 'Detalles movimientos'!$W$5:$W$1021, 0)), "") | F14: =IFERROR(INDEX('Detalles movimientos'!G$5:G$1021, MATCH(5, 'Detalles movimientos'!$W$5:$W$1021, 0)), "") | G14: =IFERROR(INDEX('Detalles movimientos'!H$5:H$1021, MATCH(5, 'Detalles movimientos'!$W$5:$W$1021, 0)), "") | H14: =IFERROR(INDEX('Detalles movimientos'!I$5:I$1021, MATCH(5, 'Detalles movimientos'!$W$5:$W$1021, 0)), "") | I14: =IFERROR(INDEX('Detalles movimientos'!M$5:M$1021, MATCH(5, 'Detalles movimientos'!$W$5:$W$1021, 0)), "") | J14: =IFERROR(INDEX('Detalles movimientos'!N$5:N$1021, MATCH(5, 'Detalles movimientos'!$W$5:$W$1021, 0)), "") | K14: =IFERROR(INDEX('Detalles movimientos'!O$5:O$1021, MATCH(5, 'Detalles movimientos'!$W$5:$W$1021, 0)), "") | L14: =IFERROR(INDEX('Detalles movimientos'!P$5:P$1021, MATCH(5, 'Detalles movimientos'!$W$5:$W$1021, 0)), "") | M14: =IFERROR(INDEX('Detalles movimientos'!S$5:S$1021, MATCH(5, 'Detalles movimientos'!$W$5:$W$1021, 0)), "")
B15: =IFERROR(INDEX('Detalles movimientos'!C$5:C$1021, MATCH(6, 'Detalles movimientos'!$W$5:$W$1021, 0)), "") | C15: =IFERROR(INDEX('Detalles movimientos'!D$5:D$1021, MATCH(6, 'Detalles movimientos'!$W$5:$W$1021, 0)), "") | D15: =IFERROR(INDEX('Detalles movimientos'!E$5:E$1021, MATCH(6, 'Detalles movimientos'!$W$5:$W$1021, 0)), "") | E15: =IFERROR(INDEX('Detalles movimientos'!F$5:F$1021, MATCH(6, 'Detalles movimientos'!$W$5:$W$1021, 0)), "") | F15: =IFERROR(INDEX('Detalles movimientos'!G$5:G$1021, MATCH(6, 'Detalles movimientos'!$W$5:$W$1021, 0)), "") | G15: =IFERROR(INDEX('Detalles movimientos'!H$5:H$1021, MATCH(6, 'Detalles movimientos'!$W$5:$W$1021, 0)), "") | H15: =IFERROR(INDEX('Detalles movimientos'!I$5:I$1021, MATCH(6, 'Detalles movimientos'!$W$5:$W$1021, 0)), "") | I15: =IFERROR(INDEX('Detalles movimientos'!M$5:M$1021, MATCH(6, 'Detalles movimientos'!$W$5:$W$1021, 0)), "") | J15: =IFERROR(INDEX('Detalles movimientos'!N$5:N$1021, MATCH(6, 'Detalles movimientos'!$W$5:$W$1021, 0)), "") | K15: =IFERROR(INDEX('Detalles movimientos'!O$5:O$1021, MATCH(6, 'Detalles movimientos'!$W$5:$W$1021, 0)), "") | L15: =IFERROR(INDEX('Detalles movimientos'!P$5:P$1021, MATCH(6, 'Detalles movimientos'!$W$5:$W$1021, 0)), "") | M15: =IFERROR(INDEX('Detalles movimientos'!S$5:S$1021, MATCH(6, 'Detalles movimientos'!$W$5:$W$1021, 0)), "")
B16: =IFERROR(INDEX('Detalles movimientos'!C$5:C$1021, MATCH(7, 'Detalles movimientos'!$W$5:$W$1021, 0)), "") | C16: =IFERROR(INDEX('Detalles movimientos'!D$5:D$1021, MATCH(7, 'Detalles movimientos'!$W$5:$W$1021, 0)), "") | D16: =IFERROR(INDEX('Detalles movimientos'!E$5:E$1021, MATCH(7, 'Detalles movimientos'!$W$5:$W$1021, 0)), "") | E16: =IFERROR(INDEX('Detalles movimientos'!F$5:F$1021, MATCH(7, 'Detalles movimientos'!$W$5:$W$1021, 0)), "") | F16: =IFERROR(INDEX('Detalles movimientos'!G$5:G$1021, MATCH(7, 'Detalles movimientos'!$W$5:$W$1021, 0)), "") | G16: =IFERROR(INDEX('Detalles movimientos'!H$5:H$1021, MATCH(7, 'Detalles movimientos'!$W$5:$W$1021, 0)), "") | H16: =IFERROR(INDEX('Detalles movimientos'!I$5:I$1021, MATCH(7, 'Detalles movimientos'!$W$5:$W$1021, 0)), "") | I16: =IFERROR(INDEX('Detalles movimientos'!M$5:M$1021, MATCH(7, 'Detalles movimientos'!$W$5:$W$1021, 0)), "") | J16: =IFERROR(INDEX('Detalles movimientos'!N$5:N$1021, MATCH(7, 'Detalles movimientos'!$W$5:$W$1021, 0)), "") | K16: =IFERROR(INDEX('Detalles movimientos'!O$5:O$1021, MATCH(7, 'Detalles movimientos'!$W$5:$W$1021, 0)), "") | L16: =IFERROR(INDEX('Detalles movimientos'!P$5:P$1021, MATCH(7, 'Detalles movimientos'!$W$5:$W$1021, 0)), "") | M16: =IFERROR(INDEX('Detalles movimientos'!S$5:S$1021, MATCH(7, 'Detalles movimientos'!$W$5:$W$1021, 0)), "")
B17: =IFERROR(INDEX('Detalles movimientos'!C$5:C$1021, MATCH(8, 'Detalles movimientos'!$W$5:$W$1021, 0)), "") | C17: =IFERROR(INDEX('Detalles movimientos'!D$5:D$1021, MATCH(8, 'Detalles movimientos'!$W$5:$W$1021, 0)), "") | D17: =IFERROR(INDEX('Detalles movimientos'!E$5:E$1021, MATCH(8, 'Detalles movimientos'!$W$5:$W$1021, 0)), "") | E17: =IFERROR(INDEX('Detalles movimientos'!F$5:F$1021, MATCH(8, 'Detalles movimientos'!$W$5:$W$1021, 0)), "") | F17: =IFERROR(INDEX('Detalles movimientos'!G$5:G$1021, MATCH(8, 'Detalles movimientos'!$W$5:$W$1021, 0)), "") | G17: =IFERROR(INDEX('Detalles movimientos'!H$5:H$1021, MATCH(8, 'Detalles movimientos'!$W$5:$W$1021, 0)), "") | H17: =IFERROR(INDEX('Detalles movimientos'!I$5:I$1021, MATCH(8, 'Detalles movimientos'!$W$5:$W$1021, 0)), "") | I17: =IFERROR(INDEX('Detalles movimientos'!M$5:M$1021, MATCH(8, 'Detalles movimientos'!$W$5:$W$1021, 0)), "") | J17: =IFERROR(INDEX('Detalles movimientos'!N$5:N$1021, MATCH(8, 'Detalles movimientos'!$W$5:$W$1021, 0)), "") | K17: =IFERROR(INDEX('Detalles movimientos'!O$5:O$1021, MATCH(8, 'Detalles movimientos'!$W$5:$W$1021, 0)), "") | L17: =IFERROR(INDEX('Detalles movimientos'!P$5:P$1021, MATCH(8, 'Detalles movimientos'!$W$5:$W$1021, 0)), "") | M17: =IFERROR(INDEX('Detalles movimientos'!S$5:S$1021, MATCH(8, 'Detalles movimientos'!$W$5:$W$1021, 0)), "")
B18: =IFERROR(INDEX('Detalles movimientos'!C$5:C$1021, MATCH(9, 'Detalles movimientos'!$W$5:$W$1021, 0)), "") | C18: =IFERROR(INDEX('Detalles movimientos'!D$5:D$1021, MATCH(9, 'Detalles movimientos'!$W$5:$W$1021, 0)), "") | D18: =IFERROR(INDEX('Detalles movimientos'!E$5:E$1021, MATCH(9, 'Detalles movimientos'!$W$5:$W$1021, 0)), "") | E18: =IFERROR(INDEX('Detalles movimientos'!F$5:F$1021, MATCH(9, 'Detalles movimientos'!$W$5:$W$1021, 0)), "") | F18: =IFERROR(INDEX('Detalles movimientos'!G$5:G$1021, MATCH(9, 'Detalles movimientos'!$W$5:$W$1021, 0)), "") | G18: =IFERROR(INDEX('Detalles movimientos'!H$5:H$1021, MATCH(9, 'Detalles movimientos'!$W$5:$W$1021, 0)), "") | H18: =IFERROR(INDEX('Detalles movimientos'!I$5:I$1021, MATCH(9, 'Detalles movimientos'!$W$5:$W$1021, 0)), "") | I18: =IFERROR(INDEX('Detalles movimientos'!M$5:M$1021, MATCH(9, 'Detalles movimientos'!$W$5:$W$1021, 0)), "") | J18: =IFERROR(INDEX('Detalles movimientos'!N$5:N$1021, MATCH(9, 'Detalles movimientos'!$W$5:$W$1021, 0)), "") | K18: =IFERROR(INDEX('Detalles movimientos'!O$5:O$1021, MATCH(9, 'Detalles movimientos'!$W$5:$W$1021, 0)), "") | L18: =IFERROR(INDEX('Detalles movimientos'!P$5:P$1021, MATCH(9, 'Detalles movimientos'!$W$5:$W$1021, 0)), "") | M18: =IFERROR(INDEX('Detalles movimientos'!S$5:S$1021, MATCH(9, 'Detalles movimientos'!$W$5:$W$1021, 0)), "")
B19: =IFERROR(INDEX('Detalles movimientos'!C$5:C$1021, MATCH(10, 'Detalles movimientos'!$W$5:$W$1021, 0)), "") | C19: =IFERROR(INDEX('Detalles movimientos'!D$5:D$1021, MATCH(10, 'Detalles movimientos'!$W$5:$W$1021, 0)), "") | D19: =IFERROR(INDEX('Detalles movimientos'!E$5:E$1021, MATCH(10, 'Detalles movimientos'!$W$5:$W$1021, 0)), "") | E19: =IFERROR(INDEX('Detalles movimientos'!F$5:F$1021, MATCH(10, 'Detalles movimientos'!$W$5:$W$1021, 0)), "") | F19: =IFERROR(INDEX('Detalles movimientos'!G$5:G$1021, MATCH(10, 'Detalles movimientos'!$W$5:$W$1021, 0)), "") | G19: =IFERROR(INDEX('Detalles movimientos'!H$5:H$1021, MATCH(10, 'Detalles movimientos'!$W$5:$W$1021, 0)), "") | H19: =IFERROR(INDEX('Detalles movimientos'!I$5:I$1021, MATCH(10, 'Detalles movimientos'!$W$5:$W$1021, 0)), "") | I19: =IFERROR(INDEX('Detalles movimientos'!M$5:M$1021, MATCH(10, 'Detalles movimientos'!$W$5:$W$1021, 0)), "") | J19: =IFERROR(INDEX('Detalles movimientos'!N$5:N$1021, MATCH(10, 'Detalles movimientos'!$W$5:$W$1021, 0)), "") | K19: =IFERROR(INDEX('Detalles movimientos'!O$5:O$1021, MATCH(10, 'Detalles movimientos'!$W$5:$W$1021, 0)), "") | L19: =IFERROR(INDEX('Detalles movimientos'!P$5:P$1021, MATCH(10, 'Detalles movimientos'!$W$5:$W$1021, 0)), "") | M19: =IFERROR(INDEX('Detalles movimientos'!S$5:S$1021, MATCH(10, 'Detalles movimientos'!$W$5:$W$1021, 0)), "")
B20: =IFERROR(INDEX('Detalles movimientos'!C$5:C$1021, MATCH(11, 'Detalles movimientos'!$W$5:$W$1021, 0)), "") | C20: =IFERROR(INDEX('Detalles movimientos'!D$5:D$1021, MATCH(11, 'Detalles movimientos'!$W$5:$W$1021, 0)), "") | D20: =IFERROR(INDEX('Detalles movimientos'!E$5:E$1021, MATCH(11, 'Detalles movimientos'!$W$5:$W$1021, 0)), "") | E20: =IFERROR(INDEX('Detalles movimientos'!F$5:F$1021, MATCH(11, 'Detalles movimientos'!$W$5:$W$1021, 0)), "") | F20: =IFERROR(INDEX('Detalles movimientos'!G$5:G$1021, MATCH(11, 'Detalles movimientos'!$W$5:$W$1021, 0)), "") | G20: =IFERROR(INDEX('Detalles movimientos'!H$5:H$1021, MATCH(11, 'Detalles movimientos'!$W$5:$W$1021, 0)), "") | H20: =IFERROR(INDEX('Detalles movimientos'!I$5:I$1021, MATCH(11, 'Detalles movimientos'!$W$5:$W$1021, 0)), "") | I20: =IFERROR(INDEX('Detalles movimientos'!M$5:M$1021, MATCH(11, 'Detalles movimientos'!$W$5:$W$1021, 0)), "") | J20: =IFERROR(INDEX('Detalles movimientos'!N$5:N$1021, MATCH(11, 'Detalles movimientos'!$W$5:$W$1021, 0)), "") | K20: =IFERROR(INDEX('Detalles movimientos'!O$5:O$1021, MATCH(11, 'Detalles movimientos'!$W$5:$W$1021, 0)), "") | L20: =IFERROR(INDEX('Detalles movimientos'!P$5:P$1021, MATCH(11, 'Detalles movimientos'!$W$5:$W$1021, 0)), "") | M20: =IFERROR(INDEX('Detalles movimientos'!S$5:S$1021, MATCH(11, 'Detalles movimientos'!$W$5:$W$1021, 0)), "")
B21: =IFERROR(INDEX('Detalles movimientos'!C$5:C$1021, MATCH(12, 'Detalles movimientos'!$W$5:$W$1021, 0)), "") | C21: =IFERROR(INDEX('Detalles movimientos'!D$5:D$1021, MATCH(12, 'Detalles movimientos'!$W$5:$W$1021, 0)), "") | D21: =IFERROR(INDEX('Detalles movimientos'!E$5:E$1021, MATCH(12, 'Detalles movimientos'!$W$5:$W$1021, 0)), "") | E21: =IFERROR(INDEX('Detalles movimientos'!F$5:F$1021, MATCH(12, 'Detalles movimientos'!$W$5:$W$1021, 0)), "") | F21: =IFERROR(INDEX('Detalles movimientos'!G$5:G$1021, MATCH(12, 'Detalles movimientos'!$W$5:$W$1021, 0)), "") | G21: =IFERROR(INDEX('Detalles movimientos'!H$5:H$1021, MATCH(12, 'Detalles movimientos'!$W$5:$W$1021, 0)), "") | H21: =IFERROR(INDEX('Detalles movimientos'!I$5:I$1021, MATCH(12, 'Detalles movimientos'!$W$5:$W$1021, 0)), "") | I21: =IFERROR(INDEX('Detalles movimientos'!M$5:M$1021, MATCH(12, 'Detalles movimientos'!$W$5:$W$1021, 0)), "") | J21: =IFERROR(INDEX('Detalles movimientos'!N$5:N$1021, MATCH(12, 'Detalles movimientos'!$W$5:$W$1021, 0)), "") | K21: =IFERROR(INDEX('Detalles movimientos'!O$5:O$1021, MATCH(12, 'Detalles movimientos'!$W$5:$W$1021, 0)), "") | L21: =IFERROR(INDEX('Detalles movimientos'!P$5:P$1021, MATCH(12, 'Detalles movimientos'!$W$5:$W$1021, 0)), "") | M21: =IFERROR(INDEX('Detalles movimientos'!S$5:S$1021, MATCH(12, 'Detalles movimientos'!$W$5:$W$1021, 0)), "")
B22: =IFERROR(INDEX('Detalles movimientos'!C$5:C$1021, MATCH(13, 'Detalles movimientos'!$W$5:$W$1021, 0)), "") | C22: =IFERROR(INDEX('Detalles movimientos'!D$5:D$1021, MATCH(13, 'Detalles movimientos'!$W$5:$W$1021, 0)), "") | D22: =IFERROR(INDEX('Detalles movimientos'!E$5:E$1021, MATCH(13, 'Detalles movimientos'!$W$5:$W$1021, 0)), "") | E22: =IFERROR(INDEX('Detalles movimientos'!F$5:F$1021, MATCH(13, 'Detalles movimientos'!$W$5:$W$1021, 0)), "") | F22: =IFERROR(INDEX('Detalles movimientos'!G$5:G$1021, MATCH(13, 'Detalles movimientos'!$W$5:$W$1021, 0)), "") | G22: =IFERROR(INDEX('Detalles movimientos'!H$5:H$1021, MATCH(13, 'Detalles movimientos'!$W$5:$W$1021, 0)), "") | H22: =IFERROR(INDEX('Detalles movimientos'!I$5:I$1021, MATCH(13, 'Detalles movimientos'!$W$5:$W$1021, 0)), "") | I22: =IFERROR(INDEX('Detalles movimientos'!M$5:M$1021, MATCH(13, 'Detalles movimientos'!$W$5:$W$1021, 0)), "") | J22: =IFERROR(INDEX('Detalles movimientos'!N$5:N$1021, MATCH(13, 'Detalles movimientos'!$W$5:$W$1021, 0)), "") | K22: =IFERROR(INDEX('Detalles movimientos'!O$5:O$1021, MATCH(13, 'Detalles movimientos'!$W$5:$W$1021, 0)), "") | L22: =IFERROR(INDEX('Detalles movimientos'!P$5:P$1021, MATCH(13, 'Detalles movimientos'!$W$5:$W$1021, 0)), "") | M22: =IFERROR(INDEX('Detalles movimientos'!S$5:S$1021, MATCH(13, 'Detalles movimientos'!$W$5:$W$1021, 0)), "")
B23: =IFERROR(INDEX('Detalles movimientos'!C$5:C$1021, MATCH(14, 'Detalles movimientos'!$W$5:$W$1021, 0)), "") | C23: =IFERROR(INDEX('Detalles movimientos'!D$5:D$1021, MATCH(14, 'Detalles movimientos'!$W$5:$W$1021, 0)), "") | D23: =IFERROR(INDEX('Detalles movimientos'!E$5:E$1021, MATCH(14, 'Detalles movimientos'!$W$5:$W$1021, 0)), "") | E23: =IFERROR(INDEX('Detalles movimientos'!F$5:F$1021, MATCH(14, 'Detalles movimientos'!$W$5:$W$1021, 0)), "") | F23: =IFERROR(INDEX('Detalles movimientos'!G$5:G$1021, MATCH(14, 'Detalles movimientos'!$W$5:$W$1021, 0)), "") | G23: =IFERROR(INDEX('Detalles movimientos'!H$5:H$1021, MATCH(14, 'Detalles movimientos'!$W$5:$W$1021, 0)), "") | H23: =IFERROR(INDEX('Detalles movimientos'!I$5:I$1021, MATCH(14, 'Detalles movimientos'!$W$5:$W$1021, 0)), "") | I23: =IFERROR(INDEX('Detalles movimientos'!M$5:M$1021, MATCH(14, 'Detalles movimientos'!$W$5:$W$1021, 0)), "") | J23: =IFERROR(INDEX('Detalles movimientos'!N$5:N$1021, MATCH(14, 'Detalles movimientos'!$W$5:$W$1021, 0)), "") | K23: =IFERROR(INDEX('Detalles movimientos'!O$5:O$1021, MATCH(14, 'Detalles movimientos'!$W$5:$W$1021, 0)), "") | L23: =IFERROR(INDEX('Detalles movimientos'!P$5:P$1021, MATCH(14, 'Detalles movimientos'!$W$5:$W$1021, 0)), "") | M23: =IFERROR(INDEX('Detalles movimientos'!S$5:S$1021, MATCH(14, 'Detalles movimientos'!$W$5:$W$1021, 0)), "")
B24: =IFERROR(INDEX('Detalles movimientos'!C$5:C$1021, MATCH(15, 'Detalles movimientos'!$W$5:$W$1021, 0)), "") | C24: =IFERROR(INDEX('Detalles movimientos'!D$5:D$1021, MATCH(15, 'Detalles movimientos'!$W$5:$W$1021, 0)), "") | D24: =IFERROR(INDEX('Detalles movimientos'!E$5:E$1021, MATCH(15, 'Detalles movimientos'!$W$5:$W$1021, 0)), "") | E24: =IFERROR(INDEX('Detalles movimientos'!F$5:F$1021, MATCH(15, 'Detalles movimientos'!$W$5:$W$1021, 0)), "") | F24: =IFERROR(INDEX('Detalles movimientos'!G$5:G$1021, MATCH(15, 'Detalles movimientos'!$W$5:$W$1021, 0)), "") | G24: =IFERROR(INDEX('Detalles movimientos'!H$5:H$1021, MATCH(15, 'Detalles movimientos'!$W$5:$W$1021, 0)), "") | H24: =IFERROR(INDEX('Detalles movimientos'!I$5:I$1021, MATCH(15, 'Detalles movimientos'!$W$5:$W$1021, 0)), "") | I24: =IFERROR(INDEX('Detalles movimientos'!M$5:M$1021, MATCH(15, 'Detalles movimientos'!$W$5:$W$1021, 0)), "") | J24: =IFERROR(INDEX('Detalles movimientos'!N$5:N$1021, MATCH(15, 'Detalles movimientos'!$W$5:$W$1021, 0)), "") | K24: =IFERROR(INDEX('Detalles movimientos'!O$5:O$1021, MATCH(15, 'Detalles movimientos'!$W$5:$W$1021, 0)), "") | L24: =IFERROR(INDEX('Detalles movimientos'!P$5:P$1021, MATCH(15, 'Detalles movimientos'!$W$5:$W$1021, 0)), "") | M24: =IFERROR(INDEX('Detalles movimientos'!S$5:S$1021, MATCH(15, 'Detalles movimientos'!$W$5:$W$1021, 0)), "")
B25: =IFERROR(INDEX('Detalles movimientos'!C$5:C$1021, MATCH(16, 'Detalles movimientos'!$W$5:$W$1021, 0)), "") | C25: =IFERROR(INDEX('Detalles movimientos'!D$5:D$1021, MATCH(16, 'Detalles movimientos'!$W$5:$W$1021, 0)), "") | D25: =IFERROR(INDEX('Detalles movimientos'!E$5:E$1021, MATCH(16, 'Detalles movimientos'!$W$5:$W$1021, 0)), "") | E25: =IFERROR(INDEX('Detalles movimientos'!F$5:F$1021, MATCH(16, 'Detalles movimientos'!$W$5:$W$1021, 0)), "") | F25: =IFERROR(INDEX('Detalles movimientos'!G$5:G$1021, MATCH(16, 'Detalles movimientos'!$W$5:$W$1021, 0)), "") | G25: =IFERROR(INDEX('Detalles movimientos'!H$5:H$1021, MATCH(16, 'Detalles movimientos'!$W$5:$W$1021, 0)), "") | H25: =IFERROR(INDEX('Detalles movimientos'!I$5:I$1021, MATCH(16, 'Detalles movimientos'!$W$5:$W$1021, 0)), "") | I25: =IFERROR(INDEX('Detalles movimientos'!M$5:M$1021, MATCH(16, 'Detalles movimientos'!$W$5:$W$1021, 0)), "") | J25: =IFERROR(INDEX('Detalles movimientos'!N$5:N$1021, MATCH(16, 'Detalles movimientos'!$W$5:$W$1021, 0)), "") | K25: =IFERROR(INDEX('Detalles movimientos'!O$5:O$1021, MATCH(16, 'Detalles movimientos'!$W$5:$W$1021, 0)), "") | L25: =IFERROR(INDEX('Detalles movimientos'!P$5:P$1021, MATCH(16, 'Detalles movimientos'!$W$5:$W$1021, 0)), "") | M25: =IFERROR(INDEX('Detalles movimientos'!S$5:S$1021, MATCH(16, 'Detalles movimientos'!$W$5:$W$1021, 0)), "")
B26: =IFERROR(INDEX('Detalles movimientos'!C$5:C$1021, MATCH(17, 'Detalles movimientos'!$W$5:$W$1021, 0)), "") | C26: =IFERROR(INDEX('Detalles movimientos'!D$5:D$1021, MATCH(17, 'Detalles movimientos'!$W$5:$W$1021, 0)), "") | D26: =IFERROR(INDEX('Detalles movimientos'!E$5:E$1021, MATCH(17, 'Detalles movimientos'!$W$5:$W$1021, 0)), "") | E26: =IFERROR(INDEX('Detalles movimientos'!F$5:F$1021, MATCH(17, 'Detalles movimientos'!$W$5:$W$1021, 0)), "") | F26: =IFERROR(INDEX('Detalles movimientos'!G$5:G$1021, MATCH(17, 'Detalles movimientos'!$W$5:$W$1021, 0)), "") | G26: =IFERROR(INDEX('Detalles movimientos'!H$5:H$1021, MATCH(17, 'Detalles movimientos'!$W$5:$W$1021, 0)), "") | H26: =IFERROR(INDEX('Detalles movimientos'!I$5:I$1021, MATCH(17, 'Detalles movimientos'!$W$5:$W$1021, 0)), "") | I26: =IFERROR(INDEX('Detalles movimientos'!M$5:M$1021, MATCH(17, 'Detalles movimientos'!$W$5:$W$1021, 0)), "") | J26: =IFERROR(INDEX('Detalles movimientos'!N$5:N$1021, MATCH(17, 'Detalles movimientos'!$W$5:$W$1021, 0)), "") | K26: =IFERROR(INDEX('Detalles movimientos'!O$5:O$1021, MATCH(17, 'Detalles movimientos'!$W$5:$W$1021, 0)), "") | L26: =IFERROR(INDEX('Detalles movimientos'!P$5:P$1021, MATCH(17, 'Detalles movimientos'!$W$5:$W$1021, 0)), "") | M26: =IFERROR(INDEX('Detalles movimientos'!S$5:S$1021, MATCH(17, 'Detalles movimientos'!$W$5:$W$1021, 0)), "")
B27: =IFERROR(INDEX('Detalles movimientos'!C$5:C$1021, MATCH(18, 'Detalles movimientos'!$W$5:$W$1021, 0)), "") | C27: =IFERROR(INDEX('Detalles movimientos'!D$5:D$1021, MATCH(18, 'Detalles movimientos'!$W$5:$W$1021, 0)), "") | D27: =IFERROR(INDEX('Detalles movimientos'!E$5:E$1021, MATCH(18, 'Detalles movimientos'!$W$5:$W$1021, 0)), "") | E27: =IFERROR(INDEX('Detalles movimientos'!F$5:F$1021, MATCH(18, 'Detalles movimientos'!$W$5:$W$1021, 0)), "") | F27: =IFERROR(INDEX('Detalles movimientos'!G$5:G$1021, MATCH(18, 'Detalles movimientos'!$W$5:$W$1021, 0)), "") | G27: =IFERROR(INDEX('Detalles movimientos'!H$5:H$1021, MATCH(18, 'Detalles movimientos'!$W$5:$W$1021, 0)), "") | H27: =IFERROR(INDEX('Detalles movimientos'!I$5:I$1021, MATCH(18, 'Detalles movimientos'!$W$5:$W$1021, 0)), "") | I27: =IFERROR(INDEX('Detalles movimientos'!M$5:M$1021, MATCH(18, 'Detalles movimientos'!$W$5:$W$1021, 0)), "") | J27: =IFERROR(INDEX('Detalles movimientos'!N$5:N$1021, MATCH(18, 'Detalles movimientos'!$W$5:$W$1021, 0)), "") | K27: =IFERROR(INDEX('Detalles movimientos'!O$5:O$1021, MATCH(18, 'Detalles movimientos'!$W$5:$W$1021, 0)), "") | L27: =IFERROR(INDEX('Detalles movimientos'!P$5:P$1021, MATCH(18, 'Detalles movimientos'!$W$5:$W$1021, 0)), "") | M27: =IFERROR(INDEX('Detalles movimientos'!S$5:S$1021, MATCH(18, 'Detalles movimientos'!$W$5:$W$1021, 0)), "")
B28: =IFERROR(INDEX('Detalles movimientos'!C$5:C$1021, MATCH(19, 'Detalles movimientos'!$W$5:$W$1021, 0)), "") | C28: =IFERROR(INDEX('Detalles movimientos'!D$5:D$1021, MATCH(19, 'Detalles movimientos'!$W$5:$W$1021, 0)), "") | D28: =IFERROR(INDEX('Detalles movimientos'!E$5:E$1021, MATCH(19, 'Detalles movimientos'!$W$5:$W$1021, 0)), "") | E28: =IFERROR(INDEX('Detalles movimientos'!F$5:F$1021, MATCH(19, 'Detalles movimientos'!$W$5:$W$1021, 0)), "") | F28: =IFERROR(INDEX('Detalles movimientos'!G$5:G$1021, MATCH(19, 'Detalles movimientos'!$W$5:$W$1021, 0)), "") | G28: =IFERROR(INDEX('Detalles movimientos'!H$5:H$1021, MATCH(19, 'Detalles movimientos'!$W$5:$W$1021, 0)), "") | H28: =IFERROR(INDEX('Detalles movimientos'!I$5:I$1021, MATCH(19, 'Detalles movimientos'!$W$5:$W$1021, 0)), "") | I28: =IFERROR(INDEX('Detalles movimientos'!M$5:M$1021, MATCH(19, 'Detalles movimientos'!$W$5:$W$1021, 0)), "") | J28: =IFERROR(INDEX('Detalles movimientos'!N$5:N$1021, MATCH(19, 'Detalles movimientos'!$W$5:$W$1021, 0)), "") | K28: =IFERROR(INDEX('Detalles movimientos'!O$5:O$1021, MATCH(19, 'Detalles movimientos'!$W$5:$W$1021, 0)), "") | L28: =IFERROR(INDEX('Detalles movimientos'!P$5:P$1021, MATCH(19, 'Detalles movimientos'!$W$5:$W$1021, 0)), "") | M28: =IFERROR(INDEX('Detalles movimientos'!S$5:S$1021, MATCH(19, 'Detalles movimientos'!$W$5:$W$1021, 0)), "")
B29: =IFERROR(INDEX('Detalles movimientos'!C$5:C$1021, MATCH(20, 'Detalles movimientos'!$W$5:$W$1021, 0)), "") | C29: =IFERROR(INDEX('Detalles movimientos'!D$5:D$1021, MATCH(20, 'Detalles movimientos'!$W$5:$W$1021, 0)), "") | D29: =IFERROR(INDEX('Detalles movimientos'!E$5:E$1021, MATCH(20, 'Detalles movimientos'!$W$5:$W$1021, 0)), "") | E29: =IFERROR(INDEX('Detalles movimientos'!F$5:F$1021, MATCH(20, 'Detalles movimientos'!$W$5:$W$1021, 0)), "") | F29: =IFERROR(INDEX('Detalles movimientos'!G$5:G$1021, MATCH(20, 'Detalles movimientos'!$W$5:$W$1021, 0)), "") | G29: =IFERROR(INDEX('Detalles movimientos'!H$5:H$1021, MATCH(20, 'Detalles movimientos'!$W$5:$W$1021, 0)), "") | H29: =IFERROR(INDEX('Detalles movimientos'!I$5:I$1021, MATCH(20, 'Detalles movimientos'!$W$5:$W$1021, 0)), "") | I29: =IFERROR(INDEX('Detalles movimientos'!M$5:M$1021, MATCH(20, 'Detalles movimientos'!$W$5:$W$1021, 0)), "") | J29: =IFERROR(INDEX('Detalles movimientos'!N$5:N$1021, MATCH(20, 'Detalles movimientos'!$W$5:$W$1021, 0)), "") | K29: =IFERROR(INDEX('Detalles movimientos'!O$5:O$1021, MATCH(20, 'Detalles movimientos'!$W$5:$W$1021, 0)), "") | L29: =IFERROR(INDEX('Detalles movimientos'!P$5:P$1021, MATCH(20, 'Detalles movimientos'!$W$5:$W$1021, 0)), "") | M29: =IFERROR(INDEX('Detalles movimientos'!S$5:S$1021, MATCH(20, 'Detalles movimientos'!$W$5:$W$1021, 0)), "")
B30: =IFERROR(INDEX('Detalles movimientos'!C$5:C$1021, MATCH(21, 'Detalles movimientos'!$W$5:$W$1021, 0)), "") | C30: =IFERROR(INDEX('Detalles movimientos'!D$5:D$1021, MATCH(21, 'Detalles movimientos'!$W$5:$W$1021, 0)), "") | D30: =IFERROR(INDEX('Detalles movimientos'!E$5:E$1021, MATCH(21, 'Detalles movimientos'!$W$5:$W$1021, 0)), "") | E30: =IFERROR(INDEX('Detalles movimientos'!F$5:F$1021, MATCH(21, 'Detalles movimientos'!$W$5:$W$1021, 0)), "") | F30: =IFERROR(INDEX('Detalles movimientos'!G$5:G$1021, MATCH(21, 'Detalles movimientos'!$W$5:$W$1021, 0)), "") | G30: =IFERROR(INDEX('Detalles movimientos'!H$5:H$1021, MATCH(21, 'Detalles movimientos'!$W$5:$W$1021, 0)), "") | H30: =IFERROR(INDEX('Detalles movimientos'!I$5:I$1021, MATCH(21, 'Detalles movimientos'!$W$5:$W$1021, 0)), "") | I30: =IFERROR(INDEX('Detalles movimientos'!M$5:M$1021, MATCH(21, 'Detalles movimientos'!$W$5:$W$1021, 0)), "") | J30: =IFERROR(INDEX('Detalles movimientos'!N$5:N$1021, MATCH(21, 'Detalles movimientos'!$W$5:$W$1021, 0)), "") | K30: =IFERROR(INDEX('Detalles movimientos'!O$5:O$1021, MATCH(21, 'Detalles movimientos'!$W$5:$W$1021, 0)), "") | L30: =IFERROR(INDEX('Detalles movimientos'!P$5:P$1021, MATCH(21, 'Detalles movimientos'!$W$5:$W$1021, 0)), "") | M30: =IFERROR(INDEX('Detalles movimientos'!S$5:S$1021, MATCH(21, 'Detalles movimientos'!$W$5:$W$1021, 0)), "")
B31: =IFERROR(INDEX('Detalles movimientos'!C$5:C$1021, MATCH(22, 'Detalles movimientos'!$W$5:$W$1021, 0)), "") | C31: =IFERROR(INDEX('Detalles movimientos'!D$5:D$1021, MATCH(22, 'Detalles movimientos'!$W$5:$W$1021, 0)), "") | D31: =IFERROR(INDEX('Detalles movimientos'!E$5:E$1021, MATCH(22, 'Detalles movimientos'!$W$5:$W$1021, 0)), "") | E31: =IFERROR(INDEX('Detalles movimientos'!F$5:F$1021, MATCH(22, 'Detalles movimientos'!$W$5:$W$1021, 0)), "") | F31: =IFERROR(INDEX('Detalles movimientos'!G$5:G$1021, MATCH(22, 'Detalles movimientos'!$W$5:$W$1021, 0)), "") | G31: =IFERROR(INDEX('Detalles movimientos'!H$5:H$1021, MATCH(22, 'Detalles movimientos'!$W$5:$W$1021, 0)), "") | H31: =IFERROR(INDEX('Detalles movimientos'!I$5:I$1021, MATCH(22, 'Detalles movimientos'!$W$5:$W$1021, 0)), "") | I31: =IFERROR(INDEX('Detalles movimientos'!M$5:M$1021, MATCH(22, 'Detalles movimientos'!$W$5:$W$1021, 0)), "") | J31: =IFERROR(INDEX('Detalles movimientos'!N$5:N$1021, MATCH(22, 'Detalles movimientos'!$W$5:$W$1021, 0)), "") | K31: =IFERROR(INDEX('Detalles movimientos'!O$5:O$1021, MATCH(22, 'Detalles movimientos'!$W$5:$W$1021, 0)), "") | L31: =IFERROR(INDEX('Detalles movimientos'!P$5:P$1021, MATCH(22, 'Detalles movimientos'!$W$5:$W$1021, 0)), "") | M31: =IFERROR(INDEX('Detalles movimientos'!S$5:S$1021, MATCH(22, 'Detalles movimientos'!$W$5:$W$1021, 0)), "")
B32: =IFERROR(INDEX('Detalles movimientos'!C$5:C$1021, MATCH(23, 'Detalles movimientos'!$W$5:$W$1021, 0)), "") | C32: =IFERROR(INDEX('Detalles movimientos'!D$5:D$1021, MATCH(23, 'Detalles movimientos'!$W$5:$W$1021, 0)), "") | D32: =IFERROR(INDEX('Detalles movimientos'!E$5:E$1021, MATCH(23, 'Detalles movimientos'!$W$5:$W$1021, 0)), "") | E32: =IFERROR(INDEX('Detalles movimientos'!F$5:F$1021, MATCH(23, 'Detalles movimientos'!$W$5:$W$1021, 0)), "") | F32: =IFERROR(INDEX('Detalles movimientos'!G$5:G$1021, MATCH(23, 'Detalles movimientos'!$W$5:$W$1021, 0)), "") | G32: =IFERROR(INDEX('Detalles movimientos'!H$5:H$1021, MATCH(23, 'Detalles movimientos'!$W$5:$W$1021, 0)), "") | H32: =IFERROR(INDEX('Detalles movimientos'!I$5:I$1021, MATCH(23, 'Detalles movimientos'!$W$5:$W$1021, 0)), "") | I32: =IFERROR(INDEX('Detalles movimientos'!M$5:M$1021, MATCH(23, 'Detalles movimientos'!$W$5:$W$1021, 0)), "") | J32: =IFERROR(INDEX('Detalles movimientos'!N$5:N$1021, MATCH(23, 'Detalles movimientos'!$W$5:$W$1021, 0)), "") | K32: =IFERROR(INDEX('Detalles movimientos'!O$5:O$1021, MATCH(23, 'Detalles movimientos'!$W$5:$W$1021, 0)), "") | L32: =IFERROR(INDEX('Detalles movimientos'!P$5:P$1021, MATCH(23, 'Detalles movimientos'!$W$5:$W$1021, 0)), "") | M32: =IFERROR(INDEX('Detalles movimientos'!S$5:S$1021, MATCH(23, 'Detalles movimientos'!$W$5:$W$1021, 0)), "")
B33: =IFERROR(INDEX('Detalles movimientos'!C$5:C$1021, MATCH(24, 'Detalles movimientos'!$W$5:$W$1021, 0)), "") | C33: =IFERROR(INDEX('Detalles movimientos'!D$5:D$1021, MATCH(24, 'Detalles movimientos'!$W$5:$W$1021, 0)), "") | D33: =IFERROR(INDEX('Detalles movimientos'!E$5:E$1021, MATCH(24, 'Detalles movimientos'!$W$5:$W$1021, 0)), "") | E33: =IFERROR(INDEX('Detalles movimientos'!F$5:F$1021, MATCH(24, 'Detalles movimientos'!$W$5:$W$1021, 0)), "") | F33: =IFERROR(INDEX('Detalles movimientos'!G$5:G$1021, MATCH(24, 'Detalles movimientos'!$W$5:$W$1021, 0)), "") | G33: =IFERROR(INDEX('Detalles movimientos'!H$5:H$1021, MATCH(24, 'Detalles movimientos'!$W$5:$W$1021, 0)), "") | H33: =IFERROR(INDEX('Detalles movimientos'!I$5:I$1021, MATCH(24, 'Detalles movimientos'!$W$5:$W$1021, 0)), "") | I33: =IFERROR(INDEX('Detalles movimientos'!M$5:M$1021, MATCH(24, 'Detalles movimientos'!$W$5:$W$1021, 0)), "") | J33: =IFERROR(INDEX('Detalles movimientos'!N$5:N$1021, MATCH(24, 'Detalles movimientos'!$W$5:$W$1021, 0)), "") | K33: =IFERROR(INDEX('Detalles movimientos'!O$5:O$1021, MATCH(24, 'Detalles movimientos'!$W$5:$W$1021, 0)), "") | L33: =IFERROR(INDEX('Detalles movimientos'!P$5:P$1021, MATCH(24, 'Detalles movimientos'!$W$5:$W$1021, 0)), "") | M33: =IFERROR(INDEX('Detalles movimientos'!S$5:S$1021, MATCH(24, 'Detalles movimientos'!$W$5:$W$1021, 0)), "")
B34: =IFERROR(INDEX('Detalles movimientos'!C$5:C$1021, MATCH(25, 'Detalles movimientos'!$W$5:$W$1021, 0)), "") | C34: =IFERROR(INDEX('Detalles movimientos'!D$5:D$1021, MATCH(25, 'Detalles movimientos'!$W$5:$W$1021, 0)), "") | D34: =IFERROR(INDEX('Detalles movimientos'!E$5:E$1021, MATCH(25, 'Detalles movimientos'!$W$5:$W$1021, 0)), "") | E34: =IFERROR(INDEX('Detalles movimientos'!F$5:F$1021, MATCH(25, 'Detalles movimientos'!$W$5:$W$1021, 0)), "") | F34: =IFERROR(INDEX('Detalles movimientos'!G$5:G$1021, MATCH(25, 'Detalles movimientos'!$W$5:$W$1021, 0)), "") | G34: =IFERROR(INDEX('Detalles movimientos'!H$5:H$1021, MATCH(25, 'Detalles movimientos'!$W$5:$W$1021, 0)), "") | H34: =IFERROR(INDEX('Detalles movimientos'!I$5:I$1021, MATCH(25, 'Detalles movimientos'!$W$5:$W$1021, 0)), "") | I34: =IFERROR(INDEX('Detalles movimientos'!M$5:M$1021, MATCH(25, 'Detalles movimientos'!$W$5:$W$1021, 0)), "") | J34: =IFERROR(INDEX('Detalles movimientos'!N$5:N$1021, MATCH(25, 'Detalles movimientos'!$W$5:$W$1021, 0)), "") | K34: =IFERROR(INDEX('Detalles movimientos'!O$5:O$1021, MATCH(25, 'Detalles movimientos'!$W$5:$W$1021, 0)), "") | L34: =IFERROR(INDEX('Detalles movimientos'!P$5:P$1021, MATCH(25, 'Detalles movimientos'!$W$5:$W$1021, 0)), "") | M34: =IFERROR(INDEX('Detalles movimientos'!S$5:S$1021, MATCH(25, 'Detalles movimientos'!$W$5:$W$1021, 0)), "")
B35: =IFERROR(INDEX('Detalles movimientos'!C$5:C$1021, MATCH(26, 'Detalles movimientos'!$W$5:$W$1021, 0)), "") | C35: =IFERROR(INDEX('Detalles movimientos'!D$5:D$1021, MATCH(26, 'Detalles movimientos'!$W$5:$W$1021, 0)), "") | D35: =IFERROR(INDEX('Detalles movimientos'!E$5:E$1021, MATCH(26, 'Detalles movimientos'!$W$5:$W$1021, 0)), "") | E35: =IFERROR(INDEX('Detalles movimientos'!F$5:F$1021, MATCH(26, 'Detalles movimientos'!$W$5:$W$1021, 0)), "") | F35: =IFERROR(INDEX('Detalles movimientos'!G$5:G$1021, MATCH(26, 'Detalles movimientos'!$W$5:$W$1021, 0)), "") | G35: =IFERROR(INDEX('Detalles movimientos'!H$5:H$1021, MATCH(26, 'Detalles movimientos'!$W$5:$W$1021, 0)), "") | H35: =IFERROR(INDEX('Detalles movimientos'!I$5:I$1021, MATCH(26, 'Detalles movimientos'!$W$5:$W$1021, 0)), "") | I35: =IFERROR(INDEX('Detalles movimientos'!M$5:M$1021, MATCH(26, 'Detalles movimientos'!$W$5:$W$1021, 0)), "") | J35: =IFERROR(INDEX('Detalles movimientos'!N$5:N$1021, MATCH(26, 'Detalles movimientos'!$W$5:$W$1021, 0)), "") | K35: =IFERROR(INDEX('Detalles movimientos'!O$5:O$1021, MATCH(26, 'Detalles movimientos'!$W$5:$W$1021, 0)), "") | L35: =IFERROR(INDEX('Detalles movimientos'!P$5:P$1021, MATCH(26, 'Detalles movimientos'!$W$5:$W$1021, 0)), "") | M35: =IFERROR(INDEX('Detalles movimientos'!S$5:S$1021, MATCH(26, 'Detalles movimientos'!$W$5:$W$1021, 0)), "")
B36: =IFERROR(INDEX('Detalles movimientos'!C$5:C$1021, MATCH(27, 'Detalles movimientos'!$W$5:$W$1021, 0)), "") | C36: =IFERROR(INDEX('Detalles movimientos'!D$5:D$1021, MATCH(27, 'Detalles movimientos'!$W$5:$W$1021, 0)), "") | D36: =IFERROR(INDEX('Detalles movimientos'!E$5:E$1021, MATCH(27, 'Detalles movimientos'!$W$5:$W$1021, 0)), "") | E36: =IFERROR(INDEX('Detalles movimientos'!F$5:F$1021, MATCH(27, 'Detalles movimientos'!$W$5:$W$1021, 0)), "") | F36: =IFERROR(INDEX('Detalles movimientos'!G$5:G$1021, MATCH(27, 'Detalles movimientos'!$W$5:$W$1021, 0)), "") | G36: =IFERROR(INDEX('Detalles movimientos'!H$5:H$1021, MATCH(27, 'Detalles movimientos'!$W$5:$W$1021, 0)), "") | H36: =IFERROR(INDEX('Detalles movimientos'!I$5:I$1021, MATCH(27, 'Detalles movimientos'!$W$5:$W$1021, 0)), "") | I36: =IFERROR(INDEX('Detalles movimientos'!M$5:M$1021, MATCH(27, 'Detalles movimientos'!$W$5:$W$1021, 0)), "") | J36: =IFERROR(INDEX('Detalles movimientos'!N$5:N$1021, MATCH(27, 'Detalles movimientos'!$W$5:$W$1021, 0)), "") | K36: =IFERROR(INDEX('Detalles movimientos'!O$5:O$1021, MATCH(27, 'Detalles movimientos'!$W$5:$W$1021, 0)), "") | L36: =IFERROR(INDEX('Detalles movimientos'!P$5:P$1021, MATCH(27, 'Detalles movimientos'!$W$5:$W$1021, 0)), "") | M36: =IFERROR(INDEX('Detalles movimientos'!S$5:S$1021, MATCH(27, 'Detalles movimientos'!$W$5:$W$1021, 0)), "")
B37: =IFERROR(INDEX('Detalles movimientos'!C$5:C$1021, MATCH(28, 'Detalles movimientos'!$W$5:$W$1021, 0)), "") | C37: =IFERROR(INDEX('Detalles movimientos'!D$5:D$1021, MATCH(28, 'Detalles movimientos'!$W$5:$W$1021, 0)), "") | D37: =IFERROR(INDEX('Detalles movimientos'!E$5:E$1021, MATCH(28, 'Detalles movimientos'!$W$5:$W$1021, 0)), "") | E37: =IFERROR(INDEX('Detalles movimientos'!F$5:F$1021, MATCH(28, 'Detalles movimientos'!$W$5:$W$1021, 0)), "") | F37: =IFERROR(INDEX('Detalles movimientos'!G$5:G$1021, MATCH(28, 'Detalles movimientos'!$W$5:$W$1021, 0)), "") | G37: =IFERROR(INDEX('Detalles movimientos'!H$5:H$1021, MATCH(28, 'Detalles movimientos'!$W$5:$W$1021, 0)), "") | H37: =IFERROR(INDEX('Detalles movimientos'!I$5:I$1021, MATCH(28, 'Detalles movimientos'!$W$5:$W$1021, 0)), "") | I37: =IFERROR(INDEX('Detalles movimientos'!M$5:M$1021, MATCH(28, 'Detalles movimientos'!$W$5:$W$1021, 0)), "") | J37: =IFERROR(INDEX('Detalles movimientos'!N$5:N$1021, MATCH(28, 'Detalles movimientos'!$W$5:$W$1021, 0)), "") | K37: =IFERROR(INDEX('Detalles movimientos'!O$5:O$1021, MATCH(28, 'Detalles movimientos'!$W$5:$W$1021, 0)), "") | L37: =IFERROR(INDEX('Detalles movimientos'!P$5:P$1021, MATCH(28, 'Detalles movimientos'!$W$5:$W$1021, 0)), "") | M37: =IFERROR(INDEX('Detalles movimientos'!S$5:S$1021, MATCH(28, 'Detalles movimientos'!$W$5:$W$1021, 0)), "")
B38: =IFERROR(INDEX('Detalles movimientos'!C$5:C$1021, MATCH(29, 'Detalles movimientos'!$W$5:$W$1021, 0)), "") | C38: =IFERROR(INDEX('Detalles movimientos'!D$5:D$1021, MATCH(29, 'Detalles movimientos'!$W$5:$W$1021, 0)), "") | D38: =IFERROR(INDEX('Detalles movimientos'!E$5:E$1021, MATCH(29, 'Detalles movimientos'!$W$5:$W$1021, 0)), "") | E38: =IFERROR(INDEX('Detalles movimientos'!F$5:F$1021, MATCH(29, 'Detalles movimientos'!$W$5:$W$1021, 0)), "") | F38: =IFERROR(INDEX('Detalles movimientos'!G$5:G$1021, MATCH(29, 'Detalles movimientos'!$W$5:$W$1021, 0)), "") | G38: =IFERROR(INDEX('Detalles movimientos'!H$5:H$1021, MATCH(29, 'Detalles movimientos'!$W$5:$W$1021, 0)), "") | H38: =IFERROR(INDEX('Detalles movimientos'!I$5:I$1021, MATCH(29, 'Detalles movimientos'!$W$5:$W$1021, 0)), "") | I38: =IFERROR(INDEX('Detalles movimientos'!M$5:M$1021, MATCH(29, 'Detalles movimientos'!$W$5:$W$1021, 0)), "") | J38: =IFERROR(INDEX('Detalles movimientos'!N$5:N$1021, MATCH(29, 'Detalles movimientos'!$W$5:$W$1021, 0)), "") | K38: =IFERROR(INDEX('Detalles movimientos'!O$5:O$1021, MATCH(29, 'Detalles movimientos'!$W$5:$W$1021, 0)), "") | L38: =IFERROR(INDEX('Detalles movimientos'!P$5:P$1021, MATCH(29, 'Detalles movimientos'!$W$5:$W$1021, 0)), "") | M38: =IFERROR(INDEX('Detalles movimientos'!S$5:S$1021, MATCH(29, 'Detalles movimientos'!$W$5:$W$1021, 0)), "")
B39: =IFERROR(INDEX('Detalles movimientos'!C$5:C$1021, MATCH(30, 'Detalles movimientos'!$W$5:$W$1021, 0)), "") | C39: =IFERROR(INDEX('Detalles movimientos'!D$5:D$1021, MATCH(30, 'Detalles movimientos'!$W$5:$W$1021, 0)), "") | D39: =IFERROR(INDEX('Detalles movimientos'!E$5:E$1021, MATCH(30, 'Detalles movimientos'!$W$5:$W$1021, 0)), "") | E39: =IFERROR(INDEX('Detalles movimientos'!F$5:F$1021, MATCH(30, 'Detalles movimientos'!$W$5:$W$1021, 0)), "") | F39: =IFERROR(INDEX('Detalles movimientos'!G$5:G$1021, MATCH(30, 'Detalles movimientos'!$W$5:$W$1021, 0)), "") | G39: =IFERROR(INDEX('Detalles movimientos'!H$5:H$1021, MATCH(30, 'Detalles movimientos'!$W$5:$W$1021, 0)), "") | H39: =IFERROR(INDEX('Detalles movimientos'!I$5:I$1021, MATCH(30, 'Detalles movimientos'!$W$5:$W$1021, 0)), "") | I39: =IFERROR(INDEX('Detalles movimientos'!M$5:M$1021, MATCH(30, 'Detalles movimientos'!$W$5:$W$1021, 0)), "") | J39: =IFERROR(INDEX('Detalles movimientos'!N$5:N$1021, MATCH(30, 'Detalles movimientos'!$W$5:$W$1021, 0)), "") | K39: =IFERROR(INDEX('Detalles movimientos'!O$5:O$1021, MATCH(30, 'Detalles movimientos'!$W$5:$W$1021, 0)), "") | L39: =IFERROR(INDEX('Detalles movimientos'!P$5:P$1021, MATCH(30, 'Detalles movimientos'!$W$5:$W$1021, 0)), "") | M39: =IFERROR(INDEX('Detalles movimientos'!S$5:S$1021, MATCH(30, 'Detalles movimientos'!$W$5:$W$1021, 0)), "")
B40: =IFERROR(INDEX('Detalles movimientos'!C$5:C$1021, MATCH(31, 'Detalles movimientos'!$W$5:$W$1021, 0)), "") | C40: =IFERROR(INDEX('Detalles movimientos'!D$5:D$1021, MATCH(31, 'Detalles movimientos'!$W$5:$W$1021, 0)), "") | D40: =IFERROR(INDEX('Detalles movimientos'!E$5:E$1021, MATCH(31, 'Detalles movimientos'!$W$5:$W$1021, 0)), "") | E40: =IFERROR(INDEX('Detalles movimientos'!F$5:F$1021, MATCH(31, 'Detalles movimientos'!$W$5:$W$1021, 0)), "") | F40: =IFERROR(INDEX('Detalles movimientos'!G$5:G$1021, MATCH(31, 'Detalles movimientos'!$W$5:$W$1021, 0)), "") | G40: =IFERROR(INDEX('Detalles movimientos'!H$5:H$1021, MATCH(31, 'Detalles movimientos'!$W$5:$W$1021, 0)), "") | H40: =IFERROR(INDEX('Detalles movimientos'!I$5:I$1021, MATCH(31, 'Detalles movimientos'!$W$5:$W$1021, 0)), "") | I40: =IFERROR(INDEX('Detalles movimientos'!M$5:M$1021, MATCH(31, 'Detalles movimientos'!$W$5:$W$1021, 0)), "") | J40: =IFERROR(INDEX('Detalles movimientos'!N$5:N$1021, MATCH(31, 'Detalles movimientos'!$W$5:$W$1021, 0)), "") | K40: =IFERROR(INDEX('Detalles movimientos'!O$5:O$1021, MATCH(31, 'Detalles movimientos'!$W$5:$W$1021, 0)), "") | L40: =IFERROR(INDEX('Detalles movimientos'!P$5:P$1021, MATCH(31, 'Detalles movimientos'!$W$5:$W$1021, 0)), "") | M40: =IFERROR(INDEX('Detalles movimientos'!S$5:S$1021, MATCH(31, 'Detalles movimientos'!$W$5:$W$1021, 0)), "")
